2025-01-10 18:08:42 - [18056] - root - INFO - PINECONE_API_KEY: [VALID]
2025-01-10 18:08:42 - [18056] - root - INFO - VERTEX_PROJECT_ID: trademark-case-agent
2025-01-10 18:08:42 - [18056] - src.config - ERROR - Failed to initialize configuration: 'AppConfig' object has no attribute 'data_dir'
2025-01-10 18:08:42 - [18056] - pinecone_plugin_interface.logging - INFO - Discovering subpackages in _NamespacePath(['C:\\Users\\jpbpr\\OneDrive\\Documents\\Hireable\\trademarkpredictor\\venv\\Lib\\site-packages\\pinecone_plugins'])
2025-01-10 18:08:42 - [18056] - pinecone_plugin_interface.logging - INFO - Looking for plugins in pinecone_plugins.inference
2025-01-10 18:08:42 - [18056] - pinecone_plugin_interface.logging - INFO - Installing plugin inference into Pinecone
2025-01-10 18:08:43 - [18056] - __main__ - INFO - Successfully connected to Pinecone
2025-01-10 18:08:43 - [18056] - __main__ - INFO - Successfully initialized Vertex AI
2025-01-10 18:08:43 - [18056] - __main__ - ERROR - PINECONE_ENVIRONMENT must be one of: gcp-starter, aws, azure
2025-01-10 18:08:43 - [18056] - __main__ - ERROR - Missing required environment variable: GOOGLE_APPLICATION_CREDENTIALS
2025-01-10 18:08:43 - [18056] - __main__ - ERROR - Created OUTPUT_DIR: data\processed
2025-01-10 18:08:43 - [18056] - __main__ - ERROR - Created LOG_DIR: logs
2025-01-10 18:08:43 - [18056] - __main__ - ERROR - Configuration verification failed: 'AppConfig' object has no attribute 'data_dir'
2025-01-10 18:08:43 - [18056] - __main__ - ERROR - Processing pipeline failed: [1002] Environment validation failed
Traceback (most recent call last):
  File "C:\Users\jpbpr\OneDrive\Documents\Hireable\trademarkpredictor\src\__main__.py", line 314, in main
    raise ConfigurationError("Environment validation failed")
src.exceptions.ConfigurationError: [1002] Environment validation failed
2025-01-10 18:08:43 - [18056] - __main__ - ERROR - Fatal error: [1002] Environment validation failed
2025-01-10 18:10:20 - [7568] - root - INFO - PINECONE_API_KEY: [VALID]
2025-01-10 18:10:20 - [7568] - root - INFO - VERTEX_PROJECT_ID: trademark-case-agent
2025-01-10 18:10:20 - [7568] - src.config - ERROR - Failed to initialize configuration: 'AppConfig' object has no attribute 'data_dir'
2025-01-10 18:10:20 - [7568] - pinecone_plugin_interface.logging - INFO - Discovering subpackages in _NamespacePath(['C:\\Users\\jpbpr\\OneDrive\\Documents\\Hireable\\trademarkpredictor\\venv\\Lib\\site-packages\\pinecone_plugins'])
2025-01-10 18:10:20 - [7568] - pinecone_plugin_interface.logging - INFO - Looking for plugins in pinecone_plugins.inference
2025-01-10 18:10:20 - [7568] - pinecone_plugin_interface.logging - INFO - Installing plugin inference into Pinecone
2025-01-10 18:10:21 - [7568] - __main__ - INFO - Successfully connected to Pinecone
2025-01-10 18:10:21 - [7568] - __main__ - INFO - Successfully initialized Vertex AI
2025-01-10 18:10:21 - [7568] - __main__ - ERROR - PINECONE_ENVIRONMENT must be one of: gcp-starter, aws, azure
2025-01-10 18:10:21 - [7568] - __main__ - ERROR - Missing required environment variable: GOOGLE_APPLICATION_CREDENTIALS
2025-01-10 18:10:21 - [7568] - __main__ - ERROR - Configuration verification failed: 'AppConfig' object has no attribute 'data_dir'
2025-01-10 18:10:21 - [7568] - __main__ - ERROR - Processing pipeline failed: [1002] Environment validation failed
Traceback (most recent call last):
  File "C:\Users\jpbpr\OneDrive\Documents\Hireable\trademarkpredictor\src\__main__.py", line 314, in main
    raise ConfigurationError("Environment validation failed")
src.exceptions.ConfigurationError: [1002] Environment validation failed
2025-01-10 18:10:21 - [7568] - __main__ - ERROR - Fatal error: [1002] Environment validation failed
2025-01-10 18:11:51 - [17232] - root - INFO - PINECONE_API_KEY: [VALID]
2025-01-10 18:11:51 - [17232] - root - INFO - PINECONE_ENVIRONMENT: gcp-starter
2025-01-10 18:11:51 - [17232] - root - INFO - VERTEX_PROJECT_ID: trademark-case-agent
2025-01-10 18:11:51 - [17232] - src.config - ERROR - Failed to initialize configuration: 'AppConfig' object has no attribute 'data_dir'
2025-01-10 18:11:51 - [17232] - pinecone_plugin_interface.logging - INFO - Discovering subpackages in _NamespacePath(['C:\\Users\\jpbpr\\OneDrive\\Documents\\Hireable\\trademarkpredictor\\venv\\Lib\\site-packages\\pinecone_plugins'])
2025-01-10 18:11:51 - [17232] - pinecone_plugin_interface.logging - INFO - Looking for plugins in pinecone_plugins.inference
2025-01-10 18:11:51 - [17232] - pinecone_plugin_interface.logging - INFO - Installing plugin inference into Pinecone
2025-01-10 18:11:52 - [17232] - __main__ - INFO - Successfully connected to Pinecone
2025-01-10 18:11:52 - [17232] - __main__ - INFO - Successfully initialized Vertex AI
2025-01-10 18:11:52 - [17232] - __main__ - ERROR - Missing required environment variable: GOOGLE_APPLICATION_CREDENTIALS
2025-01-10 18:11:52 - [17232] - __main__ - ERROR - Configuration verification failed: 'AppConfig' object has no attribute 'data_dir'
2025-01-10 18:11:52 - [17232] - __main__ - ERROR - Processing pipeline failed: [1002] Environment validation failed
Traceback (most recent call last):
  File "C:\Users\jpbpr\OneDrive\Documents\Hireable\trademarkpredictor\src\__main__.py", line 314, in main
    raise ConfigurationError("Environment validation failed")
src.exceptions.ConfigurationError: [1002] Environment validation failed
2025-01-10 18:11:52 - [17232] - __main__ - ERROR - Fatal error: [1002] Environment validation failed
